Traceback (most recent call last):
  File "/home/fccoelho/Documentos/Projects_software/text-mining-cientistas-sociais/.venv/lib/python3.12/site-packages/jupyter_cache/executors/utils.py", line 58, in single_nb_execution
    executenb(
  File "/home/fccoelho/Documentos/Projects_software/text-mining-cientistas-sociais/.venv/lib/python3.12/site-packages/nbclient/client.py", line 1305, in execute
    return NotebookClient(nb=nb, resources=resources, km=km, **kwargs).execute()
           ^^^^^^^^^^^^^^^^^^^^^^^^^^^^^^^^^^^^^^^^^^^^^^^^^^^^^^^^^^^^^^^^^^^^^
  File "/home/fccoelho/Documentos/Projects_software/text-mining-cientistas-sociais/.venv/lib/python3.12/site-packages/jupyter_core/utils/__init__.py", line 165, in wrapped
    return loop.run_until_complete(inner)
           ^^^^^^^^^^^^^^^^^^^^^^^^^^^^^^
  File "/usr/lib/python3.12/asyncio/base_events.py", line 687, in run_until_complete
    return future.result()
           ^^^^^^^^^^^^^^^
  File "/home/fccoelho/Documentos/Projects_software/text-mining-cientistas-sociais/.venv/lib/python3.12/site-packages/nbclient/client.py", line 705, in async_execute
    await self.async_execute_cell(
  File "/home/fccoelho/Documentos/Projects_software/text-mining-cientistas-sociais/.venv/lib/python3.12/site-packages/nbclient/client.py", line 1058, in async_execute_cell
    await self._check_raise_for_error(cell, cell_index, exec_reply)
  File "/home/fccoelho/Documentos/Projects_software/text-mining-cientistas-sociais/.venv/lib/python3.12/site-packages/nbclient/client.py", line 914, in _check_raise_for_error
    raise CellExecutionError.from_cell_and_msg(cell, exec_reply_content)
nbclient.exceptions.CellExecutionError: An error occurred while executing the following cell:
------------------
import os, glob, pickle
import spacy
from IPython.core.display import display, HTML, Markdown
from spacy import displacy
from sqlalchemy import create_engine
from dhbbmining import *
import ipywidgets as widgets
------------------


[31m---------------------------------------------------------------------------[39m
[31mImportError[39m                               Traceback (most recent call last)
[36mCell[39m[36m [39m[32mIn[2][39m[32m, line 3[39m
[32m      1[39m [38;5;28;01mimport[39;00m[38;5;250m [39m[34;01mos[39;00m,[38;5;250m [39m[34;01mglob[39;00m,[38;5;250m [39m[34;01mpickle[39;00m
[32m      2[39m [38;5;28;01mimport[39;00m[38;5;250m [39m[34;01mspacy[39;00m
[32m----> [39m[32m3[39m [38;5;28;01mfrom[39;00m[38;5;250m [39m[34;01mIPython[39;00m[34;01m.[39;00m[34;01mcore[39;00m[34;01m.[39;00m[34;01mdisplay[39;00m[38;5;250m [39m[38;5;28;01mimport[39;00m display, HTML, Markdown
[32m      4[39m [38;5;28;01mfrom[39;00m[38;5;250m [39m[34;01mspacy[39;00m[38;5;250m [39m[38;5;28;01mimport[39;00m displacy
[32m      5[39m [38;5;28;01mfrom[39;00m[38;5;250m [39m[34;01msqlalchemy[39;00m[38;5;250m [39m[38;5;28;01mimport[39;00m create_engine

[31mImportError[39m: cannot import name 'display' from 'IPython.core.display' (/home/fccoelho/Documentos/Projects_software/text-mining-cientistas-sociais/.venv/lib/python3.12/site-packages/IPython/core/display.py)

