Traceback (most recent call last):
  File "/usr/local/lib/python3.10/dist-packages/jupyter_cache/executors/utils.py", line 51, in single_nb_execution
    executenb(
  File "/usr/lib/python3/dist-packages/nbclient/client.py", line 1093, in execute
    return NotebookClient(nb=nb, resources=resources, km=km, **kwargs).execute()
  File "/usr/lib/python3/dist-packages/nbclient/util.py", line 84, in wrapped
    return just_run(coro(*args, **kwargs))
  File "/usr/lib/python3/dist-packages/nbclient/util.py", line 62, in just_run
    return loop.run_until_complete(coro)
  File "/usr/lib/python3.10/asyncio/base_events.py", line 646, in run_until_complete
    return future.result()
  File "/usr/lib/python3/dist-packages/nbclient/client.py", line 559, in async_execute
    await self.async_execute_cell(
  File "/usr/lib/python3/dist-packages/nbclient/client.py", line 854, in async_execute_cell
    self._check_raise_for_error(cell, exec_reply)
  File "/usr/lib/python3/dist-packages/nbclient/client.py", line 756, in _check_raise_for_error
    raise CellExecutionError.from_cell_and_msg(cell, exec_reply_content)
nbclient.exceptions.CellExecutionError: An error occurred while executing the following cell:
------------------
if os.path.exists('doc_feature_matrix.csv.gz')
    data = pd.read_csv('doc_feature_matrix.csv.gz')
else:
    gerador = gera_docv(10000)
    data = pd.DataFrame(data=np.vstack([a for a in gerador]), columns=range(100))
    data.to_csv('doc_feature_matrix.csv.gz')
data
------------------

[0;36m  Input [0;32mIn [8][0;36m[0m
[0;31m    if os.path.exists('doc_feature_matrix.csv.gz')[0m
[0m                                                  ^[0m
[0;31mSyntaxError[0m[0;31m:[0m expected ':'

SyntaxError: expected ':' (1312968881.py, line 1)

